<?xml version="1.0" encoding="utf-8"?>
<sdf version="1.5">
  <model name="robot-Insomnia">
    <pose>0 0 0 0 0 0</pose>
    <link name="Frame">
      <gravity>1</gravity>
      <self_collide>0</self_collide>
      <pose>0.410707888606449 0.36582508720247 -0.142317761951041 0 0 0</pose>
      <must_be_base_link>1</must_be_base_link>
      <velocity_decay>
        <linear>0</linear>
        <angular>0</angular>
      </velocity_decay>
      <inertial>
        <mass>2.2853082308846</mass>
        <pose>0 0 0 0 0 0</pose>
        <inertia>
          <ixx>0.0934466547821343</ixx>
          <ixy>0.00856372806329287</ixy>
          <ixz>0.000145748269011256</ixz>
          <iyy>0.194763407755728</iyy>
          <iyz>2.93077116209068E-05</iyz>
          <izz>0.113167024236241</izz>
        </inertia>
      </inertial>
      <visual name="Frame_visual">
        <pose>-0.410707888606449 -0.36582508720247 0.142317761951041 0 0 0</pose>
        <material>
          <ambient>1 0 0 1</ambient>
          <diffuse>1 0 0 1</diffuse>
        </material>
        <geometry>
          <mesh>
            <scale>1 1 1</scale>
            <uri>model://Insomnia/meshes/Frame.STL</uri>
          </mesh>
        </geometry>
      </visual>
      <sensor name="FrameCamera" type="camera">
        <visualize>1</visualize>
        <always_on>1</always_on>
        <pose>-0.388647473629622 -0.0705008179442599 -0.00315744513990174 1.5707963267949 0 3.14159265358979</pose>
        <camera name="Framecamera">
          <horizontal_fov>2.54818070791172</horizontal_fov>
          <image>
            <width>320</width>
            <height>240</height>
          </image>
          <clip>
            <near>0.1</near>
            <far>100</far>
          </clip>
        </camera>
      </sensor>
      <sensor name="laser" type="ray">
        <pose>-0.388647473629622 -0.0705008179442599 -0.00315744513990174 1.5707963267949 0 3.14</pose>
        <ray>
            <scan>
            <horizontal>
              <samples>360</samples>
              <resolution>1</resolution>
              <min_angle>0</min_angle>
              <max_angle>6.28</max_angle>
            </horizontal>
          </scan>
          <range>
            <min>0.02</min>
            <max>6</max>
            <resolution>0.01</resolution>
          </range>
          <noise>
            <type>gaussian</type>
            <mean>0.0</mean>
            <stddev>0.01</stddev>
          </noise>
        </ray>
        <always_on>1</always_on>
        <update_rate>60</update_rate>
        <visualize>true</visualize>
      </sensor>
    </link>
    <link name="RockerRight">
      <gravity>1</gravity>
      <self_collide>0</self_collide>
      <pose>0.51995422682182 0.272112066281112 -0.487941188022845 0 0 0</pose>
      <must_be_base_link>0</must_be_base_link>
      <velocity_decay>
        <linear>0</linear>
        <angular>0</angular>
      </velocity_decay>
      <inertial>
        <mass>0.571352151801313</mass>
        <pose>0 0 0 0 0 0</pose>
        <inertia>
          <ixx>0.0117846177493736</ixx>
          <ixy>0.0114113682386261</ixy>
          <ixz>0.00130304704285636</ixz>
          <iyy>0.0316533798005822</iyy>
          <iyz>0.00135722774231986</iyz>
          <izz>0.039028659107187</izz>
        </inertia>
      </inertial>
      <visual name="RockerRight_visual">
        <pose>-0.51995422682182 -0.272112066281112 0.487941188022845 0 0 0</pose>
        <material>
          <ambient>0.752941176470588 0.752941176470588 0.752941176470588 1</ambient>
          <diffuse>0.752941176470588 0.752941176470588 0.752941176470588 1</diffuse>
        </material>
        <geometry>
          <mesh>
            <scale>1 1 1</scale>
            <uri>model://Insomnia/meshes/RockerRight.STL</uri>
          </mesh>
        </geometry>
      </visual>
    </link>
    <joint name="Frame-RockerRight" type="revolute">
      <parent>Frame</parent>
      <child>RockerRight</child>
      <pose>-0.116756289049534 0.140148778808483 -0.000111679757649918 0 0 0</pose>
      <axis>
        <xyz>-0.000956519836909701 4.26435589084701E-15 0.999999542534796</xyz>
        <dynamics>
          <damping>0.1</damping>
          <friction>0.1</friction>
        </dynamics>
        <limit>
          <effort>1</effort>
        </limit>
      </axis>
    </joint>
    <link name="RockerLeft">
      <gravity>1</gravity>
      <self_collide>0</self_collide>
      <pose>0.519248658635111 0.272113357991721 0.203664937154876 0 0 0</pose>
      <must_be_base_link>0</must_be_base_link>
      <velocity_decay>
        <linear>0</linear>
        <angular>0</angular>
      </velocity_decay>
      <inertial>
        <mass>0.571352151801402</mass>
        <pose>0 0 0 0 0 0</pose>
        <inertia>
          <ixx>0.0117897406560303</ixx>
          <ixy>0.011403423503335</ixy>
          <ixz>0.00135419280649138</ixz>
          <iyy>0.0316379953533332</iyy>
          <iyz>0.00137905209460988</iyz>
          <izz>0.0390082307139841</izz>
        </inertia>
      </inertial>
      <visual name="RockerLeft_visual">
        <pose>-0.519248658635111 -0.272113357991721 -0.203664937154876 0 0 0</pose>
        <material>
          <ambient>0.752941176470588 0.752941176470588 0.752941176470588 1</ambient>
          <diffuse>0.752941176470588 0.752941176470588 0.752941176470588 1</diffuse>
        </material>
        <geometry>
          <mesh>
            <scale>1 1 1</scale>
            <uri>model://Insomnia/meshes/RockerLeft.STL</uri>
          </mesh>
        </geometry>
      </visual>
    </link>
    <joint name="Frame-RockerLeft" type="revolute">
      <parent>Frame</parent>
      <child>RockerLeft</child>
      <pose>-0.116712256183838 0.140147487097912 -0.00011163763932015 0 0 0</pose>
      <axis>
        <xyz>-0.000956519836905721 -1.42145196361567E-16 0.999999542534796</xyz>
        <dynamics>
          <damping>0.1</damping>
          <friction>0.1</friction>
        </dynamics>
        <limit>
          <effort>1</effort>
        </limit>
      </axis>
    </joint>
    <link name="BogieRight">
      <gravity>1</gravity>
      <self_collide>0</self_collide>
      <pose>0.144612473571853 0.125768137666469 -0.504799124763136 0 0 0</pose>
      <must_be_base_link>0</must_be_base_link>
      <velocity_decay>
        <linear>0</linear>
        <angular>0</angular>
      </velocity_decay>
      <inertial>
        <mass>0.373611285477876</mass>
        <pose>0 0 0 0 0 0</pose>
        <inertia>
          <ixx>0.0020331265949877</ixx>
          <ixy>0.000100571814609168</ixy>
          <ixz>1.30096342970661E-05</ixz>
          <iyy>0.0122955186047919</iyy>
          <iyz>0.000152481142034084</iyz>
          <izz>0.0136193830430852</izz>
        </inertia>
      </inertial>
      <visual name="BogieRight_visual">
        <pose>-0.144612473571853 -0.125768137666469 0.504799124763136 0 0 0</pose>
        <material>
          <ambient>0.752941176470588 0.752941176470588 0.752941176470588 1</ambient>
          <diffuse>0.752941176470588 0.752941176470588 0.752941176470588 1</diffuse>
        </material>
        <geometry>
          <mesh>
            <scale>1 1 1</scale>
            <uri>model://Insomnia/meshes/BogieRight.STL</uri>
          </mesh>
        </geometry>
      </visual>
    </link>
    <joint name="RockerRight-BogieRight" type="revolute">
      <parent>RockerRight</parent>
      <child>BogieRight</child>
      <pose>0.00088303828999059 0.0911304433288731 8.44644027497843E-07 0 0 0</pose>
      <axis>
        <xyz>-0.000956519836902709 3.64247065676515E-16 0.999999542534796</xyz>
        <dynamics>
          <damping>0.1</damping>
          <friction>0.1</friction>
        </dynamics>
        <limit>
          <effort>1</effort>
        </limit>
      </axis>
    </joint>
    <link name="Wheel5">
      <gravity>1</gravity>
      <self_collide>1</self_collide>
      <pose>0 0 0 0 0 0</pose>
      <must_be_base_link>0</must_be_base_link>
      <velocity_decay>
        <linear>0</linear>
        <angular>0</angular>
      </velocity_decay>
      <inertial>
        <mass>3</mass>
        <pose>0.840427461855749 0.0487716101855805 -0.608388621824284 0 0 0</pose>
        <inertia>
          <ixx>0.00216093</ixx>
          <ixy>0</ixy>
          <ixz>4.2E-07</ixz>
          <iyy>0.00216093</iyy>
          <iyz>0</iyz>
          <izz>0.00260391</izz>
        </inertia>
      </inertial>
      <collision name="Wheel5_collision">
        <pose>0 0 0 0 0 0</pose>
        <geometry>
          <mesh>
            <scale>1 1 1</scale>
            <uri>model://Insomnia/meshes/Wheel5_col.STL</uri>
          </mesh>
        </geometry>
        <surface>
          <contact>
            <ode />
          </contact>
          <friction>
            <ode>
              <mu>.3</mu>
              <mu2>.3</mu2>
            </ode>
          </friction>
        </surface>
      </collision>
      <visual name="Wheel5_visual">
        <pose>0 0 0 0 0 0</pose>
        <material>
          <ambient>0.145098039215686 0.145098039215686 0.145098039215686 1</ambient>
          <diffuse>0.145098039215686 0.145098039215686 0.145098039215686 1</diffuse>
        </material>
        <geometry>
          <mesh>
            <scale>1 1 1</scale>
            <uri>model://Insomnia/meshes/Wheel5.STL</uri>
          </mesh>
        </geometry>
      </visual>
    </link>
    <joint name="RockerRight-Wheel5" type="revolute">
      <parent>RockerRight</parent>
      <child>Wheel5</child>
      <pose>0.840427461855749 0.0487716101855821 -0.608388621824284 0 0 0</pose>
      <axis>
        <xyz>0.00095651983690539 3.64247065676515E-15 -0.999999542534796</xyz>
        <dynamics>
          <damping>0.1</damping>
          <friction>0.1</friction>
        </dynamics>
        <limit>
          <effort>1</effort>
        </limit>
      </axis>
    </joint>
    <link name="Wheel3">
      <gravity>1</gravity>
      <self_collide>1</self_collide>
      <pose>0 0 0 0 0 0</pose>
      <must_be_base_link>0</must_be_base_link>
      <velocity_decay>
        <linear>0</linear>
        <angular>0</angular>
      </velocity_decay>
      <inertial>
        <mass>3</mass>
        <pose>-0.0845713375672544 0.0578183169130229 -0.609273401929797 0 0 0</pose>
        <inertia>
          <ixx>0.00216093</ixx>
          <ixy>0</ixy>
          <ixz>4.2E-07</ixz>
          <iyy>0.00216093</iyy>
          <iyz>0</iyz>
          <izz>0.00260391</izz>
        </inertia>
      </inertial>
      <collision name="Wheel3_collision">
        <pose>0 0 0 0 0 0</pose>
        <geometry>
          <mesh>
            <scale>1 1 1</scale>
            <uri>model://Insomnia/meshes/Wheel3_col.STL</uri>
          </mesh>
        </geometry>
        <surface>
          <contact>
            <ode/>
          </contact>
          <friction>
            <ode>
              <mu>.3</mu>
              <mu2>.3</mu2>
            </ode>
          </friction>
        </surface>
      </collision>
      <visual name="Wheel3_visual">
        <pose>0 0 0 0 0 0</pose>
        <material>
          <ambient>0.145098039215686 0.145098039215686 0.145098039215686 1</ambient>
          <diffuse>0.145098039215686 0.145098039215686 0.145098039215686 1</diffuse>
        </material>
        <geometry>
          <mesh>
            <scale>1 1 1</scale>
            <uri>model://Insomnia/meshes/Wheel3.STL</uri>
          </mesh>
        </geometry>
      </visual>
    </link>
    <joint name="BogieRight-Wheel3" type="revolute">
      <parent>BogieRight</parent>
      <child>Wheel3</child>
      <pose>-0.0845713375672547 0.057818316913023 -0.609273401929797 0 0 0</pose>
      <axis>
        <xyz>0.000956519836921285 -5.79483968121728E-15 -0.999999542534796</xyz>
        <dynamics>
          <damping>0.1</damping>
          <friction>0.1</friction>
        </dynamics>
        <limit>
          <effort>1</effort>
        </limit>
      </axis>
    </joint>
    <link name="Wheel4">
      <gravity>1</gravity>
      <self_collide>1</self_collide>
      <pose>0 0 0 0 0 0</pose>
      <must_be_base_link>0</must_be_base_link>
      <velocity_decay>
        <linear>0</linear>
        <angular>0</angular>
      </velocity_decay>
      <inertial>
        <mass>3</mass>
        <pose>0.372610883348417 0.0533532441095961 -0.608836097866362 0 0 0</pose>
        <inertia>
          <ixx>0.00216093</ixx>
          <ixy>0</ixy>
          <ixz>4.2E-07</ixz>
          <iyy>0.00216093</iyy>
          <iyz>0</iyz>
          <izz>0.00260391</izz>
        </inertia>
      </inertial>
      <collision name="Wheel4_collision">
        <pose>0 0 0 0 0 0</pose>
        <geometry>
          <mesh>
            <scale>1 1 1</scale>
            <uri>model://Insomnia/meshes/Wheel4_col.STL</uri>
          </mesh>
        </geometry>
        <surface>
          <contact>
            <ode />
          </contact>
          <friction>
            <ode>
              <mu>.3</mu>
              <mu2>.3</mu2>
            </ode>
          </friction>
        </surface>
      </collision>
      <visual name="Wheel4_visual">
        <pose>0 0 0 0 0 0</pose>
        <material>
          <ambient>0.145098039215686 0.145098039215686 0.145098039215686 1</ambient>
          <diffuse>0.145098039215686 0.145098039215686 0.145098039215686 1</diffuse>
        </material>
        <geometry>
          <mesh>
            <scale>1 1 1</scale>
            <uri>model://Insomnia/meshes/Wheel4.STL</uri>
          </mesh>
        </geometry>
      </visual>
    </link>
    <joint name="BogieRight-Wheel4" type="revolute">
      <parent>BogieRight</parent>
      <child>Wheel4</child>
      <pose>0.372610883348417 0.0533532441095967 -0.608836097866362 0 0 0</pose>
      <axis>
        <xyz>0.00095651983691996 -5.79483968121728E-15 -0.999999542534796</xyz>
        <dynamics>
          <damping>0.1</damping>
          <friction>0.1</friction>
        </dynamics>
        <limit>
          <effort>1</effort>
        </limit>
      </axis>
    </joint>
    <link name="BogieLeft">
      <gravity>1</gravity>
      <self_collide>0</self_collide>
      <pose>0.143919493232791 0.12577623987063 0.21976415474294 0 0 0</pose>
      <must_be_base_link>0</must_be_base_link>
      <velocity_decay>
        <linear>0</linear>
        <angular>0</angular>
      </velocity_decay>
      <inertial>
        <mass>0.373611285678988</mass>
        <pose>0 0 0 0 0 0</pose>
        <inertia>
          <ixx>0.00203289412939419</ixx>
          <ixy>0.000100272513175644</ixy>
          <ixz>9.1454599268683E-06</ixz>
          <iyy>0.0122957188359747</iyy>
          <iyz>0.000153680122555828</iyz>
          <izz>0.0136189654847814</izz>
        </inertia>
      </inertial>
      <visual name="BogieLeft_visual">
        <pose>-0.143919493232791 -0.12577623987063 -0.21976415474294 0 0 0</pose>
        <material>
          <ambient>0.752941176470588 0.752941176470588 0.752941176470588 1</ambient>
          <diffuse>0.752941176470588 0.752941176470588 0.752941176470588 1</diffuse>
        </material>
        <geometry>
          <mesh>
            <scale>1 1 1</scale>
            <uri>model://Insomnia/meshes/BogieLeft.STL</uri>
          </mesh>
        </geometry>
      </visual>
    </link>
    <joint name="RockerLeft-BogieLeft" type="revolute">
      <parent>RockerLeft</parent>
      <child>BogieLeft</child>
      <pose>0.000882959162136154 0.0911223411247124 8.44568339986029E-07 0 0 0</pose>
      <axis>
        <xyz>-0.000956519836902709 3.64247065676515E-16 0.999999542534796</xyz>
        <dynamics>
          <damping>0.1</damping>
          <friction>0.1</friction>
        </dynamics>
        <limit>
          <effort>1</effort>
        </limit>
      </axis>
    </joint>
    <link name="Wheel2">
      <gravity>1</gravity>
      <self_collide>1</self_collide>
      <pose>0 0 0 0 0 0</pose>
      <must_be_base_link>0</must_be_base_link>
      <velocity_decay>
        <linear>0</linear>
        <angular>0</angular>
      </velocity_decay>
      <inertial>
        <mass>3</mass>
        <pose>0.839534919499384 0.0487716101855118 0.324725270405212 0 0 0</pose>
        <inertia>
          <ixx>0.00216093</ixx>
          <ixy>3.47655587277346E-18</ixy>
          <ixz>4.2E-07</ixz>
          <iyy>0.00216093</iyy>
          <iyz>1.95892404815211E-17</iyz>
          <izz>0.00260391</izz>
        </inertia>
      </inertial>
      <collision name="Wheel2_collision">
        <pose>0 0 0 0 0 0</pose>
        <geometry>
          <mesh>
            <scale>1 1 1</scale>
            <uri>model://Insomnia/meshes/Wheel2_col.STL</uri>
          </mesh>
        </geometry>
        <surface>
          <contact>
            <ode />
          </contact>
          <friction>
            <ode>
              <mu>.3</mu>
              <mu2>.3</mu2>
            </ode>
          </friction>
        </surface>
      </collision>
      <visual name="Wheel2_visual">
        <pose>0 0 0 0 0 0</pose>
        <material>
          <ambient>0.145098039215686 0.145098039215686 0.145098039215686 1</ambient>
          <diffuse>0.145098039215686 0.145098039215686 0.145098039215686 1</diffuse>
        </material>
        <geometry>
          <mesh>
            <scale>1 1 1</scale>
            <uri>model://Insomnia/meshes/Wheel2.STL</uri>
          </mesh>
        </geometry>
      </visual>
    </link>
    <joint name="RockerLeft-Wheel2" type="revolute">
      <parent>RockerLeft</parent>
      <child>Wheel2</child>
      <pose>0.839534919499383 0.0487716101855143 0.324725270405212 0 0 0</pose>
      <axis>
        <xyz>-0.000956519836904066 4.0563877768521E-15 0.999999542534796</xyz>
        <dynamics>
          <damping>0.1</damping>
          <friction>0.1</friction>
        </dynamics>
        <limit>
          <effort>1</effort>
        </limit>
      </axis>
    </joint>
    <link name="Wheel0">
      <gravity>1</gravity>
      <self_collide>1</self_collide>
      <pose>0 0 0 0 0 0</pose>
      <must_be_base_link>0</must_be_base_link>
      <velocity_decay>
        <linear>0</linear>
        <angular>0</angular>
      </velocity_decay>
      <inertial>
        <mass>3</mass>
        <pose>-0.0854638799237362 0.057818316913273 0.323840490299692 0 0 0</pose>
        <inertia>
          <ixx>0.00216093</ixx>
          <ixy>2.81285151089643E-16</ixy>
          <ixz>4.2E-07</ixz>
          <iyy>0.00216093</iyy>
          <iyz>9.61248489210776E-18</iyz>
          <izz>0.00260391</izz>
        </inertia>
      </inertial>
      <collision name="Wheel0_collision">
        <pose>0 0 0 0 0 0</pose>
        <geometry>
          <mesh>
            <scale>1 1 1</scale>
            <uri>model://Insomnia/meshes/Wheel0_col.STL</uri>
          </mesh>
        </geometry>
        <surface>
          <contact>
            <ode />
          </contact>
          <friction>
            <ode>
              <mu>.3</mu>
              <mu2>.3</mu2>
            </ode>
          </friction>
        </surface>
      </collision>
      <visual name="Wheel0_visual">
        <pose>0 0 0 0 0 0</pose>
        <material>
          <ambient>0.145098039215686 0.145098039215686 0.145098039215686 1</ambient>
          <diffuse>0.145098039215686 0.145098039215686 0.145098039215686 1</diffuse>
        </material>
        <geometry>
          <mesh>
            <scale>1 1 1</scale>
            <uri>model://Insomnia/meshes/Wheel0.STL</uri>
          </mesh>
        </geometry>
      </visual>
    </link>
    <joint name="BogieLeft-Wheel0" type="revolute">
      <parent>BogieLeft</parent>
      <child>Wheel0</child>
      <pose>-0.0854638799237084 0.0578183169132954 0.323840490299692 0 0 0</pose>
      <axis>
        <xyz>-0.000956519836891319 5.96040652925207E-15 0.999999542534796</xyz>
        <dynamics>
          <damping>0.1</damping>
          <friction>0.1</friction>
        </dynamics>
        <limit>
          <effort>1</effort>
        </limit>
      </axis>
    </joint>
    <link name="Wheel1">
      <gravity>1</gravity>
      <self_collide>1</self_collide>
      <pose>0 0 0 0 0 0</pose>
      <must_be_base_link>0</must_be_base_link>
      <velocity_decay>
        <linear>0</linear>
        <angular>0</angular>
      </velocity_decay>
      <inertial>
        <mass>3</mass>
        <pose>0.371718340991871 0.0533532441094065 0.324277794363129 0 0 0</pose>
        <inertia>
          <ixx>0.00216093</ixx>
          <ixy>2.67119712007332E-16</ixy>
          <ixz>4.2E-07</ixz>
          <iyy>0.00216093</iyy>
          <iyz>9.78535790540292E-18</iyz>
          <izz>0.00260391</izz>
        </inertia>
      </inertial>
      <collision name="Wheel1_collision">
        <pose>0 0 0 0 0 0</pose>
        <geometry>
          <mesh>
            <scale>1 1 1</scale>
            <uri>model://Insomnia/meshes/Wheel1_col.STL</uri>
          </mesh>
        </geometry>
        <surface>
          <contact>
            <ode />
          </contact>
          <friction>
            <ode>
              <mu>.3</mu>
              <mu2>.3</mu2>
            </ode>
          </friction>
        </surface>
      </collision>
      <visual name="Wheel1_visual">
        <pose>0 0 0 0 0 0</pose>
        <material>
          <ambient>0.145098039215686 0.145098039215686 0.145098039215686 1</ambient>
          <diffuse>0.145098039215686 0.145098039215686 0.145098039215686 1</diffuse>
        </material>
        <geometry>
          <mesh>
            <scale>1 1 1</scale>
            <uri>model://Insomnia/meshes/Wheel1.STL</uri>
          </mesh>
        </geometry>
      </visual>
    </link>
    <joint name="BogieLeft-Wheel1" type="revolute">
      <parent>BogieLeft</parent>
      <child>Wheel1</child>
      <pose>0.371718340991899 0.0533532441094299 0.324277794363129 0 0 0</pose>
      <axis>
        <xyz>-0.000956519836890822 6.04318995326946E-15 0.999999542534796</xyz>
        <dynamics>
          <damping>0.1</damping>
          <friction>0.1</friction>
        </dynamics>
        <limit>
          <effort>1</effort>
        </limit>
      </axis>
    </joint>
    <link name="DiffLeft">
      <gravity>1</gravity>
      <self_collide>0</self_collide>
      <pose>0.421010694326796 0.431744800396976 -0.123182420768956 0 0 0</pose>
      <must_be_base_link>0</must_be_base_link>
      <velocity_decay>
        <linear>0</linear>
        <angular>0</angular>
      </velocity_decay>
      <inertial>
        <mass>0.00643518498453822</mass>
        <pose>0 0 0 0 0 0</pose>
        <inertia>
          <ixx>1.44877746134927E-06</ixx>
          <ixy>2.68980178979868E-24</ixy>
          <ixz>1.26168476102296E-09</ixz>
          <iyy>1.44877866817632E-06</iyy>
          <iyz>2.83771668860937E-21</iyz>
          <izz>1.29742580096575E-07</izz>
        </inertia>
      </inertial>
      <visual name="DiffLeft_visual">
        <pose>-0.421010694326796 -0.431744800396976 0.123182420768956 0 0 0</pose>
        <material>
          <ambient>0.501960784313725 0.501960784313725 0.501960784313725 1</ambient>
          <diffuse>0.501960784313725 0.501960784313725 0.501960784313725 1</diffuse>
        </material>
        <geometry>
          <mesh>
            <scale>1 1 1</scale>
            <uri>model://Insomnia/meshes/DiffLeft.STL</uri>
          </mesh>
        </geometry>
      </visual>
    </link>
    <joint name="Frame-DiffLeft" type="revolute">
      <parent>Frame</parent>
      <child>DiffLeft</child>
      <pose>0 -5.55111512312578E-17 0 0 0 0</pose>
      <axis>
        <xyz>0.000956519836907807 -2.18548239405909E-15 -0.999999542534796</xyz>
        <dynamics>
          <damping>0</damping>
          <friction>0</friction>
        </dynamics>
        <limit>
          <effort>1</effort>
        </limit>
      </axis>
    </joint>
    <joint name="RockerLeft-DiffLeft_gearbox" type="gearbox">
      <parent>RockerLeft</parent>
      <child>DiffLeft</child>
      <gearbox_ratio>-1</gearbox_ratio>
      <gearbox_reference_body>Frame</gearbox_reference_body>
      <axis>
        <xyz>0.000956519836907807 -2.18548239405909E-15 -0.999999542534796</xyz>
      </axis>
      <axis2>
        <xyz>0.000956519836907807 -2.18548239405909E-15 -0.999999542534796</xyz>
      </axis2>
    </joint>
    <joint name="RockerLeft-DiffLeft" type="revolute">
      <parent>RockerLeft</parent>
      <child>DiffLeft</child>
      <pose>0 -5.55111512312578E-17 0 0 0 0</pose>
      <axis>
        <xyz>0.000956519836907807 -2.18548239405909E-15 -0.999999542534796</xyz>
        <dynamics>
          <damping>0</damping>
          <friction>0</friction>
        </dynamics>
        <limit>
          <effort>1</effort>
        </limit>
      </axis>
    </joint>
    <joint name="Frame-DiffLeft_gearbox" type="gearbox">
      <parent>Frame</parent>
      <child>DiffLeft</child>
      <gearbox_ratio>-1</gearbox_ratio>
      <gearbox_reference_body>RockerLeft</gearbox_reference_body>
      <axis>
        <xyz>0.000956519836907807 -2.18548239405909E-15 -0.999999542534796</xyz>
      </axis>
      <axis2>
        <xyz>0.000956519836907807 -2.18548239405909E-15 -0.999999542534796</xyz>
      </axis2>
    </joint>
    <link name="DiffRight">
      <gravity>1</gravity>
      <self_collide>0</self_collide>
      <pose>0.421057854827313 0.431744800396976 -0.172486655897019 0 0 0</pose>
      <must_be_base_link>0</must_be_base_link>
      <velocity_decay>
        <linear>0</linear>
        <angular>0</angular>
      </velocity_decay>
      <inertial>
        <mass>0.00643518498453822</mass>
        <pose>0 0 0 0 0 0</pose>
        <inertia>
          <ixx>1.44877746134927E-06</ixx>
          <ixy>2.77396310889367E-24</ixy>
          <ixz>1.26168476102296E-09</ixz>
          <iyy>1.44877866817632E-06</iyy>
          <iyz>2.95828771374765E-21</iyz>
          <izz>1.29742580096575E-07</izz>
        </inertia>
      </inertial>
      <visual name="DiffRight_visual">
        <pose>-0.421057854827313 -0.431744800396976 0.172486655897019 0 0 0</pose>
        <material>
          <ambient>0.501960784313725 0.501960784313725 0.501960784313725 1</ambient>
          <diffuse>0.501960784313725 0.501960784313725 0.501960784313725 1</diffuse>
        </material>
        <geometry>
          <mesh>
            <scale>1 1 1</scale>
            <uri>model://Insomnia/meshes/DiffRight.STL</uri>
          </mesh>
        </geometry>
      </visual>
    </link>
    <joint name="Frame-DiffRight" type="revolute">
      <parent>Frame</parent>
      <child>DiffRight</child>
      <pose>0 -5.55111512312578E-17 0 0 0 0</pose>
      <axis>
        <xyz>0.000956519836907807 -2.18548239405909E-15 -0.999999542534796</xyz>
        <dynamics>
          <damping>0</damping>
          <friction>0</friction>
        </dynamics>
        <limit>
          <effort>1</effort>
        </limit>
      </axis>
    </joint>
    <joint name="RockerRight-DiffRight_gearbox" type="gearbox">
      <parent>RockerRight</parent>
      <child>DiffRight</child>
      <gearbox_ratio>-1</gearbox_ratio>
      <gearbox_reference_body>Frame</gearbox_reference_body>
      <axis>
        <xyz>0.000956519836907807 -2.18548239405909E-15 -0.999999542534796</xyz>
      </axis>
      <axis2>
        <xyz>0.000956519836907807 -2.18548239405909E-15 -0.999999542534796</xyz>
      </axis2>
    </joint>
    <joint name="RockerRight-DiffRight" type="revolute">
      <parent>RockerRight</parent>
      <child>DiffRight</child>
      <pose>0 -5.55111512312578E-17 0 0 0 0</pose>
      <axis>
        <xyz>0.000956519836907807 -2.18548239405909E-15 -0.999999542534796</xyz>
        <dynamics>
          <damping>0</damping>
          <friction>0</friction>
        </dynamics>
        <limit>
          <effort>1</effort>
        </limit>
      </axis>
    </joint>
    <joint name="Frame-DiffRight_gearbox" type="gearbox">
      <parent>Frame</parent>
      <child>DiffRight</child>
      <gearbox_ratio>-1</gearbox_ratio>
      <gearbox_reference_body>RockerRight</gearbox_reference_body>
      <axis>
        <xyz>0.000956519836907807 -2.18548239405909E-15 -0.999999542534796</xyz>
      </axis>
      <axis2>
        <xyz>0.000956519836907807 -2.18548239405909E-15 -0.999999542534796</xyz>
      </axis2>
    </joint>
    <joint name="DiffLeft-DiffRight" type="revolute">
      <parent>DiffLeft</parent>
      <child>DiffRight</child>
      <pose>0 -5.55111512312578E-17 0 0 0 0</pose>
      <axis>
        <xyz>0.000956519836907807 -2.18548239405909E-15 -0.999999542534796</xyz>
        <dynamics>
          <damping>0</damping>
          <friction>0</friction>
        </dynamics>
        <limit>
          <effort>1</effort>
        </limit>
      </axis>
    </joint>
    <joint name="DiffLeft-DiffRight_gearbox" type="gearbox">
      <parent>Frame</parent>
      <child>DiffRight</child>
      <gearbox_ratio>-1</gearbox_ratio>
      <gearbox_reference_body>DiffLeft</gearbox_reference_body>
      <axis>
        <xyz>0.000956519836907807 -2.18548239405909E-15 -0.999999542534796</xyz>
      </axis>
      <axis2>
        <xyz>0.000956519836907807 -2.18548239405909E-15 -0.999999542534796</xyz>
      </axis2>
    </joint>
    <link name="ArmBase">
      <gravity>1</gravity>
      <self_collide>0</self_collide>
      <pose>0.132327344030457 0.447258894795329 -0.157764041521353 0 0 0</pose>
      <must_be_base_link>0</must_be_base_link>
      <velocity_decay>
        <linear>0</linear>
        <angular>0</angular>
      </velocity_decay>
      <inertial>
        <mass>0.255086070803719</mass>
        <pose>0 0 0 0 0 0</pose>
        <inertia>
          <ixx>0.00625369254445505</ixx>
          <ixy>0.000279255992229967</ixy>
          <ixz>1.64519957091313E-05</ixz>
          <iyy>0.000885444256446899</iyy>
          <iyz>0.000327552516485244</iyz>
          <izz>0.00594832958759956</izz>
        </inertia>
      </inertial>
      <visual name="ArmBase_visual">
        <pose>-0.132327344030457 -0.447258894795329 0.157764041521353 0 0 0</pose>
        <material>
          <ambient>0.752941176470588 0.752941176470588 0.752941176470588 1</ambient>
          <diffuse>0.752941176470588 0.752941176470588 0.752941176470588 1</diffuse>
        </material>
        <geometry>
          <mesh>
            <scale>1 1 1</scale>
            <uri>model://Insomnia/meshes/ArmBase.STL</uri>
          </mesh>
        </geometry>
      </visual>
    </link>
    <joint name="Frame-ArmBase" type="revolute">
      <parent>Frame</parent>
      <child>ArmBase</child>
      <pose>0.00416967187210748 -4.08555434628921E-05 0.0141788022561132 0 0 0</pose>
      <axis>
        <xyz>0.00976603109272275 0.999952311137603 9.34140674070982E-06</xyz>
        <dynamics>
          <damping>0</damping>
          <friction>0</friction>
        </dynamics>
        <limit>
	  <upper>0.50</upper>
          <lower>-0.50</lower>
          <effort>1</effort>
        </limit>
      </axis>
    </joint>
    <link name="Humerus">
      <gravity>1</gravity>
      <self_collide>0</self_collide>
      <pose>0.0707655352890135 0.608266742099012 -0.17010939471093 0 0 0</pose>
      <must_be_base_link>0</must_be_base_link>
      <velocity_decay>
        <linear>0</linear>
        <angular>0</angular>
      </velocity_decay>
      <inertial>
        <mass>0.2374324847348</mass>
        <pose>0 0 0 0 0 0</pose>
        <inertia>
          <ixx>0.00166441308251956</ixx>
          <ixy>0.000193290065738523</ixy>
          <ixz>1.35852767595601E-06</ixz>
          <iyy>0.000509987293867259</iyy>
          <iyz>0.000124304435126787</iyz>
          <izz>0.00129970492217596</izz>
        </inertia>
      </inertial>
      <visual name="Humerus_visual">
        <pose>-0.0707655352890135 -0.608266742099012 0.17010939471093 0 0 0</pose>
        <material>
          <ambient>0.501960784313725 0.501960784313725 0.501960784313725 1</ambient>
          <diffuse>0.501960784313725 0.501960784313725 0.501960784313725 1</diffuse>
        </material>
        <geometry>
          <mesh>
            <scale>1 1 1</scale>
            <uri>model://Insomnia/meshes/Humerus.STL</uri>
          </mesh>
        </geometry>
      </visual>
    </link>
    <joint name="ArmBase-Humerus" type="revolute">
      <parent>ArmBase</parent>
      <child>Humerus</child>
      <pose>0.0306773035320102 -0.185285250889499 0.00184989715709649 0 0 0</pose>
      <axis>
        <xyz>0.0569037988884811 -0.000546424058477546 -0.998379516563119</xyz>
        <dynamics>
          <damping>0</damping>
          <friction>0</friction>
        </dynamics>
        <limit>
          <upper>0</upper>
          <lower>-1.507</lower>
          <effort>1</effort>
        </limit>
      </axis>
    </joint>
    <link name="Forearm">
      <gravity>1</gravity>
      <self_collide>0</self_collide>
      <pose>-0.0263466629309719 0.682038663316889 -0.139966309899516 0 0 0</pose>
      <must_be_base_link>0</must_be_base_link>
      <velocity_decay>
        <linear>0</linear>
        <angular>0</angular>
      </velocity_decay>
      <inertial>
        <mass>0.289239698898495</mass>
        <pose>0 0 0 0 0 0</pose>
        <inertia>
          <ixx>0.000975787896240168</ixx>
          <ixy>0.000470734339495941</ixy>
          <ixz>6.95893749388849E-05</ixz>
          <iyy>0.00103798456917752</iyy>
          <iyz>8.87378860624496E-05</iyz>
          <izz>0.00104997374933202</izz>
        </inertia>
      </inertial>
      <visual name="Forearm_visual">
        <pose>0.0263466629309719 -0.682038663316889 0.139966309899516 0 0 0</pose>
        <material>
          <ambient>0.501960784313725 0.501960784313725 0.501960784313725 1</ambient>
          <diffuse>0.501960784313725 0.501960784313725 0.501960784313725 1</diffuse>
        </material>
        <geometry>
          <mesh>
            <scale>1 1 1</scale>
            <uri>model://Insomnia/meshes/Forearm.STL</uri>
          </mesh>
        </geometry>
      </visual>
    </link>
    <joint name="Humerus-Forearm" type="revolute">
      <parent>Humerus</parent>
      <child>Forearm</child>
      <pose>0.0716843992065098 0.0666879792307473 0.00404923644048125 0 0 0</pose>
      <axis>
        <xyz>0.0569037988885201 -0.000546424054447809 -0.998379516563119</xyz>
        <dynamics>
          <damping>0</damping>
          <friction>0</friction>
        </dynamics>
        <limit>
          <upper>3.14</upper>
          <lower>-0.52</lower>
          <effort>1</effort>
        </limit>
      </axis>
    </joint>
    <link name="Wrist">
      <gravity>1</gravity>
      <self_collide>0</self_collide>
      <pose>-0.158148765035772 0.578470180936007 -0.161722814495236 0 0 0</pose>
      <must_be_base_link>0</must_be_base_link>
      <velocity_decay>
        <linear>0</linear>
        <angular>0</angular>
      </velocity_decay>
      <inertial>
        <mass>0.100805605813699</mass>
        <pose>0 0 0 0 0 0</pose>
        <inertia>
          <ixx>0.000218252175439391</ixx>
          <ixy>5.10958249007669E-06</ixy>
          <ixz>4.09989186013662E-07</ixz>
          <iyy>0.000108319927974426</iyy>
          <iyz>3.55303812530806E-07</iyz>
          <izz>0.000225372825232728</izz>
        </inertia>
      </inertial>
      <visual name="Wrist_visual">
        <pose>0.158148765035772 -0.578470180936007 0.161722814495236 0 0 0</pose>
        <material>
          <ambient>0.752941176470588 0.752941176470588 0.752941176470588 1</ambient>
          <diffuse>0.752941176470588 0.752941176470588 0.752941176470588 1</diffuse>
        </material>
        <geometry>
          <mesh>
            <scale>1 1 1</scale>
            <uri>model://Insomnia/meshes/Wrist.STL</uri>
          </mesh>
        </geometry>
      </visual>
    </link>
    <joint name="Forearm-Wrist" type="revolute">
      <parent>Forearm</parent>
      <child>Wrist</child>
      <pose>-4.36437763899344E-05 -0.0199492018635742 8.43088928750846E-06 0 0 0</pose>
      <axis>
        <xyz>0.0569037988886106 -0.000546424058469869 -0.998379516563112</xyz>
        <dynamics>
          <damping>0</damping>
          <friction>0</friction>
        </dynamics>
        <limit>
          <upper>0.52</upper>
          <lower>-1.57</lower>
          <effort>1</effort>
        </limit>
      </axis>
    </joint>
    <link name="Claw">
      <gravity>1</gravity>
      <self_collide>1</self_collide>
      <pose>-0.297818001734331 0.589952645523111 -0.170823631625297 0 0 0</pose>
      <must_be_base_link>0</must_be_base_link>
      <velocity_decay>
        <linear>0</linear>
        <angular>0</angular>
      </velocity_decay>
      <inertial>
        <mass>0.179654777192158</mass>
        <pose>0 0 0 0 0 0</pose>
        <inertia>
          <ixx>0.000303712637109657</ixx>
          <ixy>0.000236529642437121</ixy>
          <ixz>3.57564331057115E-05</ixz>
          <iyy>0.000882550533152072</iyy>
          <iyz>1.38206414261477E-05</iyz>
          <izz>0.000983843689085106</izz>
        </inertia>
      </inertial>
      <!--<collision name="Claw_collision">
        <pose>0.297818001734331 -0.589952645523111 0.170823631625297 0 0 0</pose>
        <geometry>
          <mesh>
            <scale>1 1 1</scale>
            <uri>model://Insomnia/meshes/Claw_col.STL</uri>
          </mesh>
        </geometry>
        <surface>
          <contact>
            <ode />
          </contact>
          <friction>
            <ode>
              <mu>0.3</mu>
              <mu2>0.3</mu2>
            </ode>
          </friction>
        </surface>
      </collision>-->
      <visual name="Claw_visual">
        <pose>0.297818001734331 -0.589952645523111 0.170823631625297 0 0 0</pose>
        <material>
          <ambient>0.752941176470588 0.752941176470588 0.752941176470588 1</ambient>
          <diffuse>0.752941176470588 0.752941176470588 0.752941176470588 1</diffuse>
        </material>
        <geometry>
          <mesh>
            <scale>1 1 1</scale>
            <uri>model://Insomnia/meshes/Claw.STL</uri>
          </mesh>
        </geometry>
      </visual>
    </link>
    <joint name="Wrist-Claw" type="revolute">
      <parent>Wrist</parent>
      <child>Claw</child>
      <pose>-0.0042638147060074 -0.0136715600048214 0.000898383986863122 0 0 0</pose>
      <axis>
        <xyz>-0.954241592996451 0.294019363097992 -0.0545490267470125</xyz>
        <dynamics>
          <damping>0</damping>
          <friction>0</friction>
        </dynamics>
        <limit>
          <upper>3.14</upper>
          <lower>-3.14</lower>
          <effort>1</effort>
        </limit>
      </axis>
    </joint>
    <link name="Jaw">
      <gravity>1</gravity>
      <self_collide>1</self_collide>
      <pose>-0.340224857640053 0.560961308505113 -0.169973686657462 0 0 0</pose>
      <must_be_base_link>0</must_be_base_link>
      <velocity_decay>
        <linear>0</linear>
        <angular>0</angular>
      </velocity_decay>
      <inertial>
        <mass>0.0621676381785924</mass>
        <pose>0 0 0 0 0 0</pose>
        <inertia>
          <ixx>2.74048030398041E-05</ixx>
          <ixy>2.19988575880417E-05</ixy>
          <ixz>1.38767764914873E-05</ixz>
          <iyy>0.000174184688134755</iyy>
          <iyz>2.49265813723583E-06</iyz>
          <izz>0.000188157886486026</izz>
        </inertia>
      </inertial>
      <!--<collision name="Jaw_collision">
        <pose>0.340224857640053 -0.560961308505113 0.169973686657462 0 0 0</pose>
        <geometry>
          <mesh>
            <scale>1 1 1</scale>
            <uri>model://Insomnia/meshes/Jaw_col.STL</uri>
          </mesh>
        </geometry>
        <surface>
          <contact>
            <ode />
          </contact>
          <friction>
            <ode>
              <mu>0.3</mu>
              <mu2>0.3</mu2>
            </ode>
          </friction>
        </surface>
      </collision>-->
      <visual name="Jaw_visual">
        <pose>0.340224857640053 -0.560961308505113 0.169973686657462 0 0 0</pose>
        <material>
          <ambient>0.752941176470588 0.752941176470588 0.752941176470588 1</ambient>
          <diffuse>0.752941176470588 0.752941176470588 0.752941176470588 1</diffuse>
        </material>
        <geometry>
          <mesh>
            <scale>1 1 1</scale>
            <uri>model://Insomnia/meshes/Jaw.STL</uri>
          </mesh>
        </geometry>
      </visual>
    </link>
    <joint name="Claw-Jaw" type="revolute">
      <parent>Claw</parent>
      <child>Jaw</child>
      <pose>0.0353450518253436 0.00950226751648886 0.00200933154167843 0 0 0</pose>
      <axis>
        <xyz>0.0569037988886106 -0.000546424058457793 -0.998379516563112</xyz>
        <dynamics>
          <damping>0</damping>
          <friction>0</friction>
        </dynamics>
        <limit>
          <upper>0.25</upper>
          <lower>-0.707</lower>
          <effort>1</effort>
        </limit>
      </axis>
    </joint>
    <plugin name="InsomniaPlugin" filename="libInsomniaPlugin.so"/>
  </model>
</sdf>
