<?xml version="1.0" encoding="utf-8"?>
<sdf version="1.5">
    <model name="Amelio">
        <pose>0 0 0 0 0 0</pose>
        <link name="frame">
            <pose>0 0 0 0 0 0</pose>
            <must_be_base_link>1</must_be_base_link>
            <inertial>
                <mass>5.79</mass>
                <pose>0 0 0 0 0 0</pose>
                <inertia>
                    <ixx>2.814</ixx>
                    <ixy>.117</ixy>
                    <ixz>-.321</ixz>
                    <iyy>2.533</iyy>
                    <iyz>.762</iyz>
                    <izz>.601</izz>
                </inertia>
            </inertial>
            <visual name="visual">
                <pose>0 0 0 0 0 0</pose>
                <material>
                    <ambient>1 0 0 1</ambient>
                    <diffuse>1 0 0 1</diffuse>
                </material>
                <geometry>
                    <mesh>
                        <uri>model://robot-Amelio/meshes/frame.stl</uri>
                    </mesh>
                </geometry>
            </visual>
            <collision name="collision">
                <pose>0 0 0 0 0 0</pose>
                <geometry>
                    <cylinder>
                        <radius>0.1</radius>
                        <length>0.15</length>
                    </cylinder>
                </geometry>
            </collision>
        </link>

        <link name="diff_bar">
            <!--<pose>0.173 0 -.032 0 0 0</pose>-->
            <pose>0 0 0 0 0 0</pose>
            <inertial>
                <mass>0.278</mass>
                <pose>0 0 0 0 0 0</pose>
                <inertia>
                    <ixx>2.814</ixx>
                    <ixy>.117</ixy>
                    <ixz>-.321</ixz>
                    <iyy>2.533</iyy>
                    <iyz>.762</iyz>
                    <izz>.601</izz>
                </inertia>
            </inertial>
            <visual name="visual">
                <pose>0 0 0 0 0 0</pose>
                <material>
                    <ambient>.2 .2 .2 1</ambient>
                    <diffuse>.5 .5 .5 1</diffuse>
                </material>
                <geometry>
                    <mesh>
                        <uri>model://robot-Amelio/meshes/diff_bar.stl</uri>
                    </mesh>
                </geometry>
            </visual>
        </link>

        <joint name="frame-diff_bar" type="revolute">
            <pose>.173 0 -.032 0 0 0</pose>
            <parent>frame</parent>
            <child>diff_bar</child>
            <axis>
                <xyz>0 0 1</xyz>
            </axis>
        </joint>

        <!--Robot Left Side Drive System-->
        <link name="diff_con_left">
            <pose>0 0 0 0 0 0</pose>
            <inertial>
                <mass>0.278</mass>
                <pose>0 0 0 0 0 0</pose>
                <inertia>
                    <ixx>2.814</ixx>
                    <ixy>.117</ixy>
                    <ixz>-.321</ixz>
                    <iyy>2.533</iyy>
                    <iyz>.762</iyz>
                    <izz>.601</izz>
                </inertia>
            </inertial>
            <visual name="visual">
                <pose>0 0 0 0 0 0</pose>
                <material>
                    <ambient>.2 .2 .2 1</ambient>
                    <diffuse>.5 .5 .5 1</diffuse>
                </material>
                <geometry>
                    <mesh>
                        <uri>model://robot-Amelio/meshes/diff_con_left.stl</uri>
                    </mesh>
                </geometry>
            </visual>
        </link>

        <joint name="diff_bar-diff_con_left" type="ball">
            <pose>.173 .242 -.027 0 0 0</pose>
            <parent>diff_bar</parent>
            <child>diff_con_left</child>
        </joint>

        <link name="sqr_mid_left">
            <pose>0 0 0 0 0 0</pose>
            <inertial>
                <mass>0.278</mass>
                <pose>0 0 0 0 0 0</pose>
                <inertia>
                    <ixx>2.814</ixx>
                    <ixy>.117</ixy>
                    <ixz>-.321</ixz>
                    <iyy>2.533</iyy>
                    <iyz>.762</iyz>
                    <izz>.601</izz>
                </inertia>
            </inertial>
            <visual name="visual">
                <pose>0 0 0 0 0 0</pose>
                <material>
                    <ambient>.2 .2 .2 1</ambient>
                    <diffuse>.5 .5 .5 1</diffuse>
                </material>
                <geometry>
                    <mesh>
                        <uri>model://robot-Amelio/meshes/sqr_mid_left.stl</uri>
                    </mesh>
                </geometry>
            </visual>
        </link>

        <joint name="diff_con_left-sqr_mid_left" type="ball">
            <pose>0 .242 -.027 0 0 0</pose>
            <parent>diff_con_left</parent>
            <child>sqr_mid_left</child>
        </joint>

        <joint name="frame-sqr_mid_left" type="revolute">
            <pose>0 0.243 0 0 0 0</pose>
            <parent>frame</parent>
            <child>sqr_mid_left</child>
            <axis>
                <xyz>0 1 0</xyz>
            </axis>
        </joint>


        <link name="bogie_con_left">
            <pose>0 0 0 0 0 0</pose>
            <inertial>
                <mass>0.278</mass>
                <pose>0 0 0 0 0 0</pose>
                <inertia>
                    <ixx>2.814</ixx>
                    <ixy>.117</ixy>
                    <ixz>-.321</ixz>
                    <iyy>2.533</iyy>
                    <iyz>.762</iyz>
                    <izz>.601</izz>
                </inertia>
            </inertial>
            <visual name="visual">
                <pose>0 0 0 0 0 0</pose>
                <material>
                    <ambient>.2 .2 .2 1</ambient>
                    <diffuse>.5 .5 .5 1</diffuse>
                </material>
                <geometry>
                    <mesh>
                        <uri>model://robot-Amelio/meshes/bogie_con_left.stl</uri>
                    </mesh>
                </geometry>
            </visual>
        </link>

        <joint name="sqr_mid_left-bogie_con_left" type="revolute">
            <pose>-0.076 .270 .001 0 0 0</pose>
            <parent>sqr_mid_left</parent>
            <child>bogie_con_left</child>
            <axis>
                <xyz>0 1 0</xyz>
            </axis>
        </joint>

        <link name="bogie_left">
            <pose>0 0 0 0 0 0</pose>
            <inertial>
                <mass>0.278</mass>
                <pose>0 0 0 0 0 0</pose>
                <inertia>
                    <ixx>2.814</ixx>
                    <ixy>.117</ixy>
                    <ixz>-.321</ixz>
                    <iyy>2.533</iyy>
                    <iyz>.762</iyz>
                    <izz>.601</izz>
                </inertia>
            </inertial>
            <visual name="visual">
                <pose>0 0 0 0 0 0</pose>
                <material>
                    <ambient>.2 .2 .2 1</ambient>
                    <diffuse>.5 .5 .5 1</diffuse>
                </material>
                <geometry>
                    <mesh>
                        <uri>model://robot-Amelio/meshes/bogie_left.stl</uri>
                    </mesh>
                </geometry>
            </visual>
        </link>

        <joint name="bogie_con_left-bogie_left" type="revolute">
            <pose>-.279 .27 0 0 0 0</pose>
            <parent>bogie_con_left</parent>
            <child>bogie_left</child>
            <axis>
                <xyz>0 1 0</xyz>
            </axis>
        </joint>

        <link name="wheel1">
            <pose>0 0 0 0 0 0</pose>
            <inertial>
                <mass>0.278</mass>
                <pose>0 0 0 0 0 0</pose>
                <inertia>
                    <ixx>2.814</ixx>
                    <ixy>.117</ixy>
                    <ixz>-.321</ixz>
                    <iyy>2.533</iyy>
                    <iyz>.762</iyz>
                    <izz>.601</izz>
                </inertia>
            </inertial>
            <visual name="visual">
                <pose>0 0 0 0 0 0</pose>
                <material>
                    <ambient>1 0 0 1</ambient>
                    <diffuse>1 0 0 1</diffuse>
                </material>
                <geometry>
                    <mesh>
                        <uri>model://robot-Amelio/meshes/wheel1.stl</uri>
                    </mesh>
                </geometry>
            </visual>
            <collision name="collision">
                <pose>-.0326 .399 -.131 1.5708 0 0</pose>
                <geometry>
                    <cylinder>
                        <radius>0.11</radius>
                        <length>.171</length>
                    </cylinder>
                </geometry>
            </collision>
        </link>

        <joint name="bogie_left-wheel1" type="revolute">
            <pose>-.0326 .484 -.131 0 0 0</pose>
            <parent>bogie_left</parent>
            <child>wheel1</child>
            <axis>
                <xyz>0 1 0</xyz>
            </axis>
        </joint>

        <link name="wheel2">
            <pose>0 0 0 0 0 0</pose>
            <inertial>
                <mass>0.278</mass>
                <pose>0 0 0 0 0 0</pose>
                <inertia>
                    <ixx>2.814</ixx>
                    <ixy>.117</ixy>
                    <ixz>-.321</ixz>
                    <iyy>2.533</iyy>
                    <iyz>.762</iyz>
                    <izz>.601</izz>
                </inertia>
            </inertial>
            <visual name="visual">
                <pose>0 0 0 0 0 0</pose>
                <material>
                    <ambient>1 0 0 1</ambient>
                    <diffuse>1 0 0 1</diffuse>
                </material>
                <geometry>
                    <mesh>
                        <uri>model://robot-Amelio/meshes/wheel2.stl</uri>
                    </mesh>
                </geometry>
            </visual>
            <collision name="collision">
                <pose>-.692 .399 -.127 1.5708 0 0</pose>
                <geometry>
                    <cylinder>
                        <radius>0.11</radius>
                        <length>.171</length>
                    </cylinder>
                </geometry>
            </collision>
        </link>

        <joint name="bogie_left-wheel2" type="revolute">
            <pose>-.692 .484 -.127 0 0 0</pose>
            <parent>bogie_left</parent>
            <child>wheel2</child>
            <axis>
                <xyz>0 1 0</xyz>
            </axis>
        </joint>

        <link name="rocker_left">
        <pose>0 0 0 0 0 0</pose>
        <inertial>
            <mass>0.278</mass>
            <pose>0 0 0 0 0 0</pose>
            <inertia>
                <ixx>2.814</ixx>
                <ixy>.117</ixy>
                <ixz>-.321</ixz>
                <iyy>2.533</iyy>
                <iyz>.762</iyz>
                <izz>.601</izz>
            </inertia>
        </inertial>
        <visual name="visual">
            <pose>0 0 0 0 0 0</pose>
            <material>
                <ambient>.2 .2 .2 1</ambient>
                <diffuse>.5 .5 .5 1</diffuse>
            </material>
            <geometry>
                <mesh>
                    <uri>model://robot-Amelio/meshes/rocker_left.stl</uri>
                </mesh>
            </geometry>
        </visual>
        </link>

        <joint name="sqr_mid_left-rocker_left" type="revolute">
          <pose>0.0762 0.27 0 0 0 0</pose>
          <parent>sqr_mid_left</parent>
          <child>rocker_left</child>
          <axis>
              <xyz>0 1 0</xyz>
          </axis>
        </joint>

        <link name="wheel0">
        <pose>0 0 0 0 0 0</pose>
        <inertial>
            <mass>0.278</mass>
            <pose>0 0 0 0 0 0</pose>
            <inertia>
                <ixx>2.814</ixx>
                <ixy>.117</ixy>
                <ixz>-.321</ixz>
                <iyy>2.533</iyy>
                <iyz>.762</iyz>
                <izz>.601</izz>
            </inertia>
        </inertial>
        <visual name="visual">
            <pose>0 0 0 0 0 0</pose>
            <material>
                <ambient>1 0 0 1</ambient>
                <diffuse>1 0 0 1</diffuse>
            </material>
            <geometry>
                <mesh>
                    <uri>model://robot-Amelio/meshes/wheel0.stl</uri>
                </mesh>
            </geometry>
        </visual>
        <collision name="collision">
            <pose> .602 .399 -.127 1.5708 0 0</pose>
            <geometry>
                <cylinder>
                    <radius>0.11</radius>
                    <length>.171</length>
                </cylinder>
            </geometry>
        </collision>
        </link>

        <joint name="rocker_left-wheel0" type="revolute">
          <pose> .602 .484 -.127 0 0 0</pose>
          <parent>rocker_left</parent>
          <child>wheel0</child>
          <axis>
              <xyz>0 1 0</xyz>
          </axis>
        </joint>

        <link name="linear_actuator_left_front">
        <pose>0 0 0 0 0 0</pose>
        <inertial>
            <mass>0.278</mass>
            <pose>0 0 0 0 0 0</pose>
            <inertia>
                <ixx>2.814</ixx>
                <ixy>.117</ixy>
                <ixz>-.321</ixz>
                <iyy>2.533</iyy>
                <iyz>.762</iyz>
                <izz>.601</izz>
            </inertia>
        </inertial>
        <visual name="visual">
            <pose>0 0 0 0 0 0</pose>
            <material>
                <ambient>.2 .2 .2 1</ambient>
                <diffuse>.5 .5 .5 1</diffuse>
            </material>
            <geometry>
                <mesh>
                    <uri>model://robot-Amelio/meshes/linear_actuator_left_front.stl</uri>
                </mesh>
            </geometry>
        </visual>
        </link>

        <joint name="sqr_mid_left-linear_actuator_left_front" type="revolute">
          <pose> .152 .259 .213 0 0 0</pose>
          <parent>sqr_mid_left</parent>
          <child>linear_actuator_left_front</child>
          <axis>
              <xyz>0 1 0</xyz>
          </axis>
        </joint>

        <joint name="rocker_left-linear_actuator_left_front" type="revolute">
          <pose> .186 .280 0 0 0 0</pose>
          <parent>rocker_left</parent>
          <child>linear_actuator_left_front</child>
          <axis>
              <xyz>0 1 0</xyz>
          </axis>
        </joint>

        <link name="linear_actuator_left_back">
        <pose>0 0 0 0 0 0</pose>
        <inertial>
            <mass>0.278</mass>
            <pose>0 0 0 0 0 0</pose>
            <inertia>
                <ixx>2.814</ixx>
                <ixy>.117</ixy>
                <ixz>-.321</ixz>
                <iyy>2.533</iyy>
                <iyz>.762</iyz>
                <izz>.601</izz>
            </inertia>
        </inertial>
        <visual name="visual">
            <pose>0 0 0 0 0 0</pose>
            <material>
                <ambient>.2 .2 .2 1</ambient>
                <diffuse>.5 .5 .5 1</diffuse>
            </material>
            <geometry>
                <mesh>
                    <uri>model://robot-Amelio/meshes/linear_actuator_left_back.stl</uri>
                </mesh>
            </geometry>
        </visual>
        </link>

        <joint name="sqr_mid_left-linear_actuator_left_back" type="revolute">
          <pose> -.152 .259 .238 0 0 0</pose>
          <parent>sqr_mid_left</parent>
          <child>linear_actuator_left_back</child>
          <axis>
              <xyz>0 1 0</xyz>
          </axis>
        </joint>

        <joint name="bogie_con_left-linear_actuator_left_back" type="revolute">
          <pose> -.186 .256 0 0 0 0</pose>
          <parent>bogie_con_left</parent>
          <child>linear_actuator_left_back</child>
          <axis>
              <xyz>0 1 0</xyz>
          </axis>
        </joint>

        <!--Robot Right Side Drive System-->
        <link name="diff_con_right">
            <pose>0 0 0 0 0 0</pose>
            <inertial>
                <mass>0.278</mass>
                <pose>0 0 0 0 0 0</pose>
                <inertia>
                    <ixx>2.814</ixx>
                    <ixy>.117</ixy>
                    <ixz>-.321</ixz>
                    <iyy>2.533</iyy>
                    <iyz>.762</iyz>
                    <izz>.601</izz>
                </inertia>
            </inertial>
            <visual name="visual">
                <pose>0 0 0 0 0 0</pose>
                <material>
                    <ambient>.2 .2 .2 1</ambient>
                    <diffuse>.5 .5 .5 1</diffuse>
                </material>
                <geometry>
                    <mesh>
                        <uri>model://robot-Amelio/meshes/diff_con_right.stl</uri>
                    </mesh>
                </geometry>
            </visual>
        </link>

        <joint name="diff_bar-diff_con_right" type="ball">
            <pose>.173 -.242 -.027 0 0 0</pose>
            <parent>diff_bar</parent>
            <child>diff_con_right</child>
        </joint>

        <link name="sqr_mid_right">
            <pose>0 0 0 0 0 0</pose>
            <inertial>
                <mass>0.278</mass>
                <pose>0 0 0 0 0 0</pose>
                <inertia>
                    <ixx>2.814</ixx>
                    <ixy>.117</ixy>
                    <ixz>-.321</ixz>
                    <iyy>2.533</iyy>
                    <iyz>.762</iyz>
                    <izz>.601</izz>
                </inertia>
            </inertial>
            <visual name="visual">
                <pose>0 0 0 0 0 0</pose>
                <material>
                    <ambient>.2 .2 .2 1</ambient>
                    <diffuse>.5 .5 .5 1</diffuse>
                </material>
                <geometry>
                    <mesh>
                        <uri>model://robot-Amelio/meshes/sqr_mid_right.stl</uri>
                    </mesh>
                </geometry>
            </visual>
        </link>

        <joint name="diff_con_right-sqr_mid_right" type="ball">
            <pose>0 -.242 -.027 0 0 0</pose>
            <parent>diff_con_right</parent>
            <child>sqr_mid_right</child>
        </joint>

        <joint name="frame-sqr_mid_right" type="revolute">
            <pose>0 -0.243 0 0 0 0</pose>
            <parent>frame</parent>
            <child>sqr_mid_right</child>
            <axis>
                <xyz>0 1 0</xyz>
            </axis>
        </joint>

        <link name="bogie_con_right">
            <pose>0 0 0 0 0 0</pose>
            <inertial>
                <mass>0.278</mass>
                <pose>0 0 0 0 0 0</pose>
                <inertia>
                    <ixx>2.814</ixx>
                    <ixy>.117</ixy>
                    <ixz>-.321</ixz>
                    <iyy>2.533</iyy>
                    <iyz>.762</iyz>
                    <izz>.601</izz>
                </inertia>
            </inertial>
            <visual name="visual">
                <pose>0 0 0 0 0 0</pose>
                <material>
                    <ambient>.2 .2 .2 1</ambient>
                    <diffuse>.5 .5 .5 1</diffuse>
                </material>
                <geometry>
                    <mesh>
                        <uri>model://robot-Amelio/meshes/bogie_con_right.stl</uri>
                    </mesh>
                </geometry>
            </visual>
        </link>

        <joint name="sqr_mid_right-bogie_con_right" type="revolute">
            <pose>-0.076 -.270 .001 0 0 0</pose>
            <parent>sqr_mid_right</parent>
            <child>bogie_con_right</child>
            <axis>
                <xyz>0 1 0</xyz>
            </axis>
        </joint>

        <link name="bogie_right">
            <pose>0 0 0 0 0 0</pose>
            <inertial>
                <mass>0.278</mass>
                <pose>0 0 0 0 0 0</pose>
                <inertia>
                    <ixx>2.814</ixx>
                    <ixy>.117</ixy>
                    <ixz>-.321</ixz>
                    <iyy>2.533</iyy>
                    <iyz>.762</iyz>
                    <izz>.601</izz>
                </inertia>
            </inertial>
            <visual name="visual">
                <pose>0 0 0 0 0 0</pose>
                <material>
                    <ambient>.2 .2 .2 1</ambient>
                    <diffuse>.5 .5 .5 1</diffuse>
                </material>
                <geometry>
                    <mesh>
                        <uri>model://robot-Amelio/meshes/bogie_right.stl</uri>
                    </mesh>
                </geometry>
            </visual>
        </link>

        <joint name="bogie_con_right-bogie_right" type="revolute">
            <pose>-.279 -.27 0 0 0 0</pose>
            <parent>bogie_con_right</parent>
            <child>bogie_right</child>
            <axis>
                <xyz>0 1 0</xyz>
            </axis>
        </joint>

        <link name="wheel4">
            <pose>0 0 0 0 0 0</pose>
            <inertial>
                <mass>0.278</mass>
                <pose>0 0 0 0 0 0</pose>
                <inertia>
                    <ixx>2.814</ixx>
                    <ixy>.117</ixy>
                    <ixz>-.321</ixz>
                    <iyy>2.533</iyy>
                    <iyz>.762</iyz>
                    <izz>.601</izz>
                </inertia>
            </inertial>
            <visual name="visual">
                <pose>0 0 0 0 0 0</pose>
                <material>
                    <ambient>1 0 0 1</ambient>
                    <diffuse>1 0 0 1</diffuse>
                </material>
                <geometry>
                    <mesh>
                        <uri>model://robot-Amelio/meshes/wheel4.stl</uri>
                    </mesh>
                </geometry>
            </visual>
            <collision name="collision">
                <pose>-.0326 -.399 -.131 1.5708 0 0</pose>
                <geometry>
                    <cylinder>
                        <radius>0.11</radius>
                        <length>.171</length>
                    </cylinder>
                </geometry>
            </collision>
        </link>

        <joint name="bogie_right-wheel4" type="revolute">
            <pose>-.0326 -.484 -.131 0 0 0</pose>
            <parent>bogie_right</parent>
            <child>wheel4</child>
            <axis>
                <xyz>0 1 0</xyz>
            </axis>
        </joint>

        <link name="wheel3">
            <pose>0 0 0 0 0 0</pose>
            <inertial>
                <mass>0.278</mass>
                <pose>0 0 0 0 0 0</pose>
                <inertia>
                    <ixx>2.814</ixx>
                    <ixy>.117</ixy>
                    <ixz>-.321</ixz>
                    <iyy>2.533</iyy>
                    <iyz>.762</iyz>
                    <izz>.601</izz>
                </inertia>
            </inertial>
            <visual name="visual">
                <pose>0 0 0 0 0 0</pose>
                <material>
                    <ambient>1 0 0 1</ambient>
                    <diffuse>1 0 0 1</diffuse>
                </material>
                <geometry>
                    <mesh>
                        <uri>model://robot-Amelio/meshes/wheel3.stl</uri>
                    </mesh>
                </geometry>
            </visual>
            <collision name="collision">
                <pose>-.692 -.399 -.127 1.5708 0 0</pose>
                <geometry>
                    <cylinder>
                        <radius>0.11</radius>
                        <length>.171</length>
                    </cylinder>
                </geometry>
            </collision>
        </link>

        <joint name="bogie_right-wheel3" type="revolute">
            <pose>-.692 -.484 -.127 0 0 0</pose>
            <parent>bogie_right</parent>
            <child>wheel3</child>
            <axis>
                <xyz>0 1 0</xyz>
            </axis>
        </joint>

        <!--Robot Right Side Drive System-->
        <!--<link name="diff_con_right">
        </link>

        <joint name="diff_bar-diff_con_right" type="spherical">
        </joint>

        <link name="sqr_mid_right">
        </link>

        <joint name="diff_con_right-sqr_mid_right" type="spherical">
        </joint>-->






























    </model>
</sdf>
